[2024-05-22T08:27:21.403+0000] {taskinstance.py:1159} INFO - Dependencies all met for dep_context=non-requeueable deps ti=<TaskInstance: RestCountries.get_countries_info manual__2024-05-22T08:27:20.311328+00:00 [queued]>
[2024-05-22T08:27:21.408+0000] {taskinstance.py:1159} INFO - Dependencies all met for dep_context=requeueable deps ti=<TaskInstance: RestCountries.get_countries_info manual__2024-05-22T08:27:20.311328+00:00 [queued]>
[2024-05-22T08:27:21.408+0000] {taskinstance.py:1361} INFO - Starting attempt 1 of 1
[2024-05-22T08:27:21.414+0000] {taskinstance.py:1382} INFO - Executing <Task(_PythonDecoratedOperator): get_countries_info> on 2024-05-22 08:27:20.311328+00:00
[2024-05-22T08:27:21.417+0000] {standard_task_runner.py:57} INFO - Started process 3835 to run task
[2024-05-22T08:27:21.419+0000] {standard_task_runner.py:84} INFO - Running: ['***', 'tasks', 'run', 'RestCountries', 'get_countries_info', 'manual__2024-05-22T08:27:20.311328+00:00', '--job-id', '34', '--raw', '--subdir', 'DAGS_FOLDER/RestCountries.py', '--cfg-path', '/tmp/tmptczn6e5_']
[2024-05-22T08:27:21.421+0000] {standard_task_runner.py:85} INFO - Job 34: Subtask get_countries_info
[2024-05-22T08:27:21.446+0000] {task_command.py:416} INFO - Running <TaskInstance: RestCountries.get_countries_info manual__2024-05-22T08:27:20.311328+00:00 [running]> on host b8721ae4b73c
[2024-05-22T08:27:21.477+0000] {taskinstance.py:1662} INFO - Exporting env vars: AIRFLOW_CTX_DAG_OWNER='***' AIRFLOW_CTX_DAG_ID='RestCountries' AIRFLOW_CTX_TASK_ID='get_countries_info' AIRFLOW_CTX_EXECUTION_DATE='2024-05-22T08:27:20.311328+00:00' AIRFLOW_CTX_TRY_NUMBER='1' AIRFLOW_CTX_DAG_RUN_ID='manual__2024-05-22T08:27:20.311328+00:00'
[2024-05-22T08:28:38.798+0000] {taskinstance.py:1937} ERROR - Task failed with exception
Traceback (most recent call last):
  File "/home/airflow/.local/lib/python3.8/site-packages/urllib3/connectionpool.py", line 715, in urlopen
    httplib_response = self._make_request(
  File "/home/airflow/.local/lib/python3.8/site-packages/urllib3/connectionpool.py", line 404, in _make_request
    self._validate_conn(conn)
  File "/home/airflow/.local/lib/python3.8/site-packages/urllib3/connectionpool.py", line 1058, in _validate_conn
    conn.connect()
  File "/home/airflow/.local/lib/python3.8/site-packages/urllib3/connection.py", line 419, in connect
    self.sock = ssl_wrap_socket(
  File "/home/airflow/.local/lib/python3.8/site-packages/urllib3/util/ssl_.py", line 449, in ssl_wrap_socket
    ssl_sock = _ssl_wrap_socket_impl(
  File "/home/airflow/.local/lib/python3.8/site-packages/urllib3/util/ssl_.py", line 493, in _ssl_wrap_socket_impl
    return ssl_context.wrap_socket(sock, server_hostname=server_hostname)
  File "/usr/local/lib/python3.8/ssl.py", line 500, in wrap_socket
    return self.sslsocket_class._create(
  File "/usr/local/lib/python3.8/ssl.py", line 1073, in _create
    self.do_handshake()
  File "/usr/local/lib/python3.8/ssl.py", line 1342, in do_handshake
    self._sslobj.do_handshake()
ssl.SSLEOFError: EOF occurred in violation of protocol (_ssl.c:1131)

During handling of the above exception, another exception occurred:

Traceback (most recent call last):
  File "/home/airflow/.local/lib/python3.8/site-packages/requests/adapters.py", line 486, in send
    resp = conn.urlopen(
  File "/home/airflow/.local/lib/python3.8/site-packages/urllib3/connectionpool.py", line 799, in urlopen
    retries = retries.increment(
  File "/home/airflow/.local/lib/python3.8/site-packages/urllib3/util/retry.py", line 592, in increment
    raise MaxRetryError(_pool, url, error or ResponseError(cause))
urllib3.exceptions.MaxRetryError: HTTPSConnectionPool(host='restcountries.com', port=443): Max retries exceeded with url: /v3/all (Caused by SSLError(SSLEOFError(8, 'EOF occurred in violation of protocol (_ssl.c:1131)')))

During handling of the above exception, another exception occurred:

Traceback (most recent call last):
  File "/home/airflow/.local/lib/python3.8/site-packages/airflow/decorators/base.py", line 221, in execute
    return_value = super().execute(context)
  File "/home/airflow/.local/lib/python3.8/site-packages/airflow/operators/python.py", line 192, in execute
    return_value = self.execute_callable()
  File "/home/airflow/.local/lib/python3.8/site-packages/airflow/operators/python.py", line 209, in execute_callable
    return self.python_callable(*self.op_args, **self.op_kwargs)
  File "/opt/airflow/dags/RestCountries.py", line 20, in get_countries_info
    response = requests.get(url)
  File "/home/airflow/.local/lib/python3.8/site-packages/requests/api.py", line 73, in get
    return request("get", url, params=params, **kwargs)
  File "/home/airflow/.local/lib/python3.8/site-packages/requests/api.py", line 59, in request
    return session.request(method=method, url=url, **kwargs)
  File "/home/airflow/.local/lib/python3.8/site-packages/requests/sessions.py", line 589, in request
    resp = self.send(prep, **send_kwargs)
  File "/home/airflow/.local/lib/python3.8/site-packages/requests/sessions.py", line 703, in send
    r = adapter.send(request, **kwargs)
  File "/home/airflow/.local/lib/python3.8/site-packages/requests/adapters.py", line 517, in send
    raise SSLError(e, request=request)
requests.exceptions.SSLError: HTTPSConnectionPool(host='restcountries.com', port=443): Max retries exceeded with url: /v3/all (Caused by SSLError(SSLEOFError(8, 'EOF occurred in violation of protocol (_ssl.c:1131)')))
[2024-05-22T08:28:38.806+0000] {taskinstance.py:1400} INFO - Marking task as FAILED. dag_id=RestCountries, task_id=get_countries_info, execution_date=20240522T082720, start_date=20240522T082721, end_date=20240522T082838
[2024-05-22T08:28:38.813+0000] {standard_task_runner.py:104} ERROR - Failed to execute job 34 for task get_countries_info (HTTPSConnectionPool(host='restcountries.com', port=443): Max retries exceeded with url: /v3/all (Caused by SSLError(SSLEOFError(8, 'EOF occurred in violation of protocol (_ssl.c:1131)'))); 3835)
[2024-05-22T08:28:38.831+0000] {local_task_job_runner.py:228} INFO - Task exited with return code 1
[2024-05-22T08:28:38.851+0000] {taskinstance.py:2778} INFO - 0 downstream tasks scheduled from follow-on schedule check
